Workbook

Sheet 1.a Compute rate of return
B2: Using the closing stock prices of 49 monthly data calculate the monthly rate of returns for 48 months commencing from 1st of January 2021 to 1st of January 2025
B3: Table 1.a.1
B4: Monthly return of Pro Medicus Limited (ASX.PME) | F4: Monthly return of CSL Limited (ASX.CSL) | J4: Monthly return of Xero Limited (ASX:XRO) | N4: Monthly return of NEXTDC Limited (ASX:NXT) | R4: Monthly retun of Telstra Group Limited (ASX:TLS) | V4: Monthly retun of TPG Telecom Limited (ASX:TPG) | Z4: Monthly return of Commonwealth Bank (ASX:CBA) | AD4: Monthly return of Australian Finance Group Limited (ASX:AFG)
B5: {=_xlfn.STOCKHISTORY("XASX:PME","01-01-2021","01-01-2025",2,1,0,1)} -> Date | C5: Close | D5: Monthly rate of return | F5: {=_xlfn.STOCKHISTORY("XASX:CSL","01-01-2021","01-01-2025",2,1,0,1)} -> Date | G5: Close | J5: {=_xlfn.STOCKHISTORY("XASX:XRO","01-01-2021","01-01-2025",2,1,0,1)} -> Date | K5: Close | N5: {=_xlfn.STOCKHISTORY("XASX:NXT","01-01-2021","01-01-2025",2,1,0,1)} -> Date | O5: Close | R5: {=_xlfn.STOCKHISTORY("XASX:TLS","01-01-2021","01-01-2025",2,1,0,1)} -> Date | S5: Close | V5: {=_xlfn.STOCKHISTORY("XASX:TPG","01-01-2021","01-01-2025",2,1,0,1)} -> Date | W5: Close | Z5: {=_xlfn.STOCKHISTORY("XASX:CBA","01-01-2021","01-01-2025",2,1,0,1)} -> Date | AA5: Close | AD5: {=_xlfn.STOCKHISTORY("XASX:AFG","01-01-2021","01-01-2025",2,1,0,1)} -> Date | AE5: Close | AI5: STOCKHISTORY("XASX:PME","01-01-2021","01-01-2025",2,1,0,1) | AK5: Symbol | AL5: Company | AM5: Category | AN5: Category code | AO5: Category code for chosen assests
A6: 0 | B6: 44197 | C6: 42.84 | F6: 44197 | G6: 271.72 | J6: 44197 | K6: 129.89 | N6: 44197 | O6: 11.6 | R6: 44197 | S6: 3.12 | V6: 44197 | W6: 7.4 | Z6: 44197 | AA6: 83.51 | AD6: 44197 | AE6: 2.74 | AK6: (ASX:PME) | AL6: Pro Medicus Limited | AM6: Healthcare | AN6: S1 | AO6: S11
A7: 1 | B7: 44228 | C7: 44.35 | D7: =(C7-C6)/C6 -> 0.035247432 | F7: 44228 | G7: 262.59 | H7: =(G7-G6)/G6 -> -0.033600765 | J7: 44228 | K7: 118.43 | L7: =(K7-K6)/K6 -> -0.088228501 | N7: 44228 | O7: 11.2 | P7: =(O7-O6)/O6 -> -0.034482759 | R7: 44228 | S7: 3.08 | T7: =(S7-S6)/S6 -> -0.012820513 | V7: 44228 | W7: 6.8 | X7: =(W7-W6)/W6 -> -0.081081081 | Z7: 44228 | AA7: 81.56 | AB7: =(AA7-AA6)/AA6 -> -0.023350497 | AD7: 44228 | AE7: 2.81 | AF7: =(AE7-AE6)/AE6 -> 0.025547445 | AI7: TFC-symbal of the company- get it from Yahoo finance while looking for th category | AK7: (ASX.CSL) | AL7: CSL Limited | AO7: S12
A8: 2 | B8: 44256 | C8: 41.33 | D8: =(C8-C7)/C7 -> -0.068094701 | F8: 44256 | G8: 264.65 | H8: =(G8-G7)/G7 -> 0.0078449294 | J8: 44256 | K8: 126.53 | L8: =(K8-K7)/K7 -> 0.068394832 | N8: 44256 | O8: 10.42 | P8: =(O8-O7)/O7 -> -0.069642857 | R8: 44256 | S8: 3.4 | T8: =(S8-S7)/S7 -> 0.1038961 | V8: 44256 | W8: 6.33 | X8: =(W8-W7)/W7 -> -0.069117647 | Z8: 44256 | AA8: 86.1 | AB8: =(AA8-AA7)/AA7 -> 0.055664541 | AD8: 44256 | AE8: 2.63 | AF8: =(AE8-AE7)/AE7 -> -0.06405694 | AI8: 01-01-2021-starting month -given in UA format (MM/DD/YYYY) | AK8: (ASX:XRO) | AL8: Xero Limited | AM8: Technology | AN8: S2 | AO8: S21
A9: 3 | B9: 44287 | C9: 47.21 | D9: =(C9-C8)/C8 -> 0.14226954 | F9: 44287 | G9: 271.16 | H9: =(G9-G8)/G8 -> 0.024598526 | J9: 44287 | K9: 141.56 | L9: =(K9-K8)/K8 -> 0.11878606 | N9: 44287 | O9: 11.59 | P9: =(O9-O8)/O8 -> 0.11228407 | R9: 44287 | S9: 3.39 | T9: =(S9-S8)/S8 -> -0.0029411765 | V9: 44287 | W9: 5.51 | X9: =(W9-W8)/W8 -> -0.12954186 | Z9: 44287 | AA9: 89.04 | AB9: =(AA9-AA8)/AA8 -> 0.034146341 | AD9: 44287 | AE9: 2.82 | AF9: =(AE9-AE8)/AE8 -> 0.072243346 | AI9: 01-01-2025 -ending date -(MM-DD-YYYY) 49 months | AK9: (ASX:NXT) | AL9: NEXTDC Limited | AO9: S22
A10: 4 | B10: 44317 | C10: 46.11 | D10: =(C10-C9)/C9 -> -0.023300148 | F10: 44317 | G10: 290.21 | H10: =(G10-G9)/G9 -> 0.070253725 | J10: 44317 | K10: 132.65 | L10: =(K10-K9)/K9 -> -0.062941509 | N10: 44317 | O10: 10.88 | P10: =(O10-O9)/O9 -> -0.061259707 | R10: 44317 | S10: 3.52 | T10: =(S10-S9)/S9 -> 0.038348083 | V10: 44317 | W10: 5.21 | X10: =(W10-W9)/W9 -> -0.054446461 | Z10: 44317 | AA10: 99.72 | AB10: =(AA10-AA9)/AA9 -> 0.11994609 | AD10: 44317 | AE10: 2.82 | AF10: =(AE10-AE9)/AE9 -> 0 | AI10: 2 -frequency for monthly data (interval:0 daily, 1 weekly, 2 monthly) | AK10: (ASX:TLS) | AL10: Telstra Group Limited | AM10: Communication services | AN10: S3 | AO10: S31
A11: 5 | B11: 44348 | C11: 58.72 | D11: =(C11-C10)/C10 -> 0.27347647 | F11: 44348 | G11: 285.19 | H11: =(G11-G10)/G10 -> -0.017297819 | J11: 44348 | K11: 137.1 | L11: =(K11-K10)/K10 -> 0.033546928 | N11: 44348 | O11: 11.86 | P11: =(O11-O10)/O10 -> 0.090073529 | R11: 44348 | S11: 3.76 | T11: =(S11-S10)/S10 -> 0.068181818 | V11: 44348 | W11: 6.26 | X11: =(W11-W10)/W10 -> 0.20153551 | Z11: 44348 | AA11: 99.87 | AB11: =(AA11-AA10)/AA10 -> 0.0015042118 | AD11: 44348 | AE11: 2.85 | AF11: =(AE11-AE10)/AE10 -> 0.010638298 | AI11: 1 -show the header | AK11: (ASX:TPG) | AL11: TPG Telecom Limited | AO11: S32
A12: 6 | B12: 44378 | C12: 57.98 | D12: =(C12-C11)/C11 -> -0.01260218 | F12: 44378 | G12: 288.91 | H12: =(G12-G11)/G11 -> 0.013043936 | J12: 44378 | K12: 140.28 | L12: =(K12-K11)/K11 -> 0.023194748 | N12: 44378 | O12: 12.75 | P12: =(O12-O11)/O11 -> 0.075042159 | R12: 44378 | S12: 3.78 | T12: =(S12-S11)/S11 -> 0.0053191489 | V12: 44378 | W12: 6.18 | X12: =(W12-W11)/W11 -> -0.012779553 | Z12: 44378 | AA12: 99.65 | AB12: =(AA12-AA11)/AA11 -> -0.0022028637 | AD12: 44378 | AE12: 2.59 | AF12: =(AE12-AE11)/AE11 -> -0.09122807 | AI12: 0-date | AK12: (ASX:CBA) | AL12: Commonwealth Bank | AM12: Financial Services | AN12: S4 | AO12: S41
A13: 7 | B13: 44409 | C13: 63.07 | D13: =(C13-C12)/C12 -> 0.087788893 | F13: 44409 | G13: 311.94 | H13: =(G13-G12)/G12 -> 0.079713406 | J13: 44409 | K13: 151.82 | L13: =(K13-K12)/K12 -> 0.082264043 | N13: 44409 | O13: 13.24 | P13: =(O13-O12)/O12 -> 0.038431373 | R13: 44409 | S13: 3.84 | T13: =(S13-S12)/S12 -> 0.015873016 | V13: 44409 | W13: 6.16 | X13: =(W13-W12)/W12 -> -0.003236246 | Z13: 44409 | AA13: 100.12 | AB13: =(AA13-AA12)/AA12 -> 0.0047165078 | AD13: 44409 | AE13: 3.03 | AF13: =(AE13-AE12)/AE12 -> 0.16988417 | AI13: 1-closing price | AK13: (ASX:AFG) | AL13: Australian Finance Group Limited | AO13: S42
A14: 8 | B14: 44440 | C14: 54.61 | D14: =(C14-C13)/C13 -> -0.13413667 | F14: 44440 | G14: 293.4 | H14: =(G14-G13)/G13 -> -0.059434507 | J14: 44440 | K14: 139 | L14: =(K14-K13)/K13 -> -0.084442102 | N14: 44440 | O14: 12.03 | P14: =(O14-O13)/O13 -> -0.091389728 | R14: 44440 | S14: 3.93 | T14: =(S14-S13)/S13 -> 0.0234375 | V14: 44440 | W14: 7.06 | X14: =(W14-W13)/W13 -> 0.1461039 | Z14: 44440 | AA14: 104.33 | AB14: =(AA14-AA13)/AA13 -> 0.042049541 | AD14: 44440 | AE14: 2.77 | AF14: =(AE14-AE13)/AE13 -> -0.085808581
A15: 9 | B15: 44470 | C15: 53.28 | D15: =(C15-C14)/C14 -> -0.024354514 | F15: 44470 | G15: 300.49 | H15: =(G15-G14)/G14 -> 0.024164963 | J15: 44470 | K15: 149.51 | L15: =(K15-K14)/K14 -> 0.075611511 | N15: 44470 | O15: 11.74 | P15: =(O15-O14)/O14 -> -0.024106401 | R15: 44470 | S15: 3.82 | T15: =(S15-S14)/S14 -> -0.027989822 | V15: 44470 | W15: 6.75 | X15: =(W15-W14)/W14 -> -0.043909348 | Z15: 44470 | AA15: 104.68 | AB15: =(AA15-AA14)/AA14 -> 0.0033547398 | AD15: 44470 | AE15: 2.63 | AF15: =(AE15-AE14)/AE14 -> -0.050541516 | AI15: Calculate the monthly rate of return shown in D column
A16: 10 | B16: 44501 | C16: 62.48 | D16: =(C16-C15)/C15 -> 0.17267267 | F16: 44501 | G16: 306.79 | H16: =(G16-G15)/G15 -> 0.020965756 | J16: 44501 | K16: 144.84 | L16: =(K16-K15)/K15 -> -0.031235369 | N16: 44501 | O16: 12.1 | P16: =(O16-O15)/O15 -> 0.030664395 | R16: 44501 | S16: 4.07 | T16: =(S16-S15)/S15 -> 0.065445026 | V16: 44501 | W16: 6.75 | X16: =(W16-W15)/W15 -> 0 | Z16: 44501 | AA16: 93.18 | AB16: =(AA16-AA15)/AA15 -> -0.10985862 | AD16: 44501 | AE16: 2.7 | AF16: =(AE16-AE15)/AE15 -> 0.02661597
A17: 11 | B17: 44531 | C17: 62.44 | D17: =(C17-C16)/C16 -> -0.00064020487 | F17: 44531 | G17: 290.72 | H17: =(G17-G16)/G16 -> -0.052381108 | J17: 44531 | K17: 141.44 | L17: =(K17-K16)/K16 -> -0.023474178 | N17: 44531 | O17: 12.79 | P17: =(O17-O16)/O16 -> 0.057024793 | R17: 44531 | S17: 4.18 | T17: =(S17-S16)/S16 -> 0.027027027 | V17: 44531 | W17: 5.89 | X17: =(W17-W16)/W16 -> -0.12740741 | Z17: 44531 | AA17: 101 | AB17: =(AA17-AA16)/AA16 -> 0.083923589 | AD17: 44531 | AE17: 2.7 | AF17: =(AE17-AE16)/AE16 -> 0 | AI17: column F,J,N…... should be completed by students
A18: 12 | B18: 44562 | C18: 45.1 | D18: =(C18-C17)/C17 -> -0.2777066 | F18: 44562 | G18: 260.35 | H18: =(G18-G17)/G17 -> -0.10446478 | J18: 44562 | K18: 112.91 | L18: =(K18-K17)/K17 -> -0.20171097 | N18: 44562 | O18: 10.67 | P18: =(O18-O17)/O17 -> -0.1657545 | R18: 44562 | S18: 3.92 | T18: =(S18-S17)/S17 -> -0.062200957 | V18: 44562 | W18: 5.9 | X18: =(W18-W17)/W17 -> 0.0016977929 | Z18: 44562 | AA18: 93.74 | AB18: =(AA18-AA17)/AA17 -> -0.071881188 | AD18: 44562 | AE18: 2.2 | AF18: =(AE18-AE17)/AE17 -> -0.18518519
A19: 13 | B19: 44593 | C19: 46.73 | D19: =(C19-C18)/C18 -> 0.036141907 | F19: 44593 | G19: 259.98 | H19: =(G19-G18)/G18 -> -0.0014211638 | J19: 44593 | K19: 93.73 | L19: =(K19-K18)/K18 -> -0.16986981 | N19: 44593 | O19: 10.63 | P19: =(O19-O18)/O18 -> -0.0037488285 | R19: 44593 | S19: 3.96 | T19: =(S19-S18)/S18 -> 0.010204082 | V19: 44593 | W19: 5.59 | X19: =(W19-W18)/W18 -> -0.052542373 | Z19: 44593 | AA19: 93.46 | AB19: =(AA19-AA18)/AA18 -> -0.0029869853 | AD19: 44593 | AE19: 2.21 | AF19: =(AE19-AE18)/AE18 -> 0.0045454545
A20: 14 | B20: 44621 | C20: 48.99 | D20: =(C20-C19)/C19 -> 0.048362936 | F20: 44621 | G20: 268.15 | H20: =(G20-G19)/G19 -> 0.031425494 | J20: 44621 | K20: 102.75 | L20: =(K20-K19)/K19 -> 0.096233863 | N20: 44621 | O20: 11.66 | P20: =(O20-O19)/O19 -> 0.096895579 | R20: 44621 | S20: 3.96 | T20: =(S20-S19)/S19 -> 0 | V20: 44621 | W20: 6.05 | X20: =(W20-W19)/W19 -> 0.082289803 | Z20: 44621 | AA20: 105.77 | AB20: =(AA20-AA19)/AA19 -> 0.1317141 | AD20: 44621 | AE20: 2.15 | AF20: =(AE20-AE19)/AE19 -> -0.027149321
A21: 15 | B21: 44652 | C21: 47.48 | D21: =(C21-C20)/C20 -> -0.030822617 | F21: 44652 | G21: 273.3 | H21: =(G21-G20)/G20 -> 0.019205668 | J21: 44652 | K21: 96.35 | L21: =(K21-K20)/K20 -> -0.062287105 | N21: 44652 | O21: 11.28 | P21: =(O21-O20)/O20 -> -0.032590051 | R21: 44652 | S21: 4.04 | T21: =(S21-S20)/S20 -> 0.02020202 | V21: 44652 | W21: 5.88 | X21: =(W21-W20)/W20 -> -0.028099174 | Z21: 44652 | AA21: 103.88 | AB21: =(AA21-AA20)/AA20 -> -0.017868961 | AD21: 44652 | AE21: 2.04 | AF21: =(AE21-AE20)/AE20 -> -0.051162791
A22: 16 | B22: 44682 | C22: 42.13 | D22: =(C22-C21)/C21 -> -0.11267902 | F22: 44682 | G22: 271.83 | H22: =(G22-G21)/G21 -> -0.0053787047 | J22: 44682 | K22: 89.29 | L22: =(K22-K21)/K21 -> -0.07327452 | N22: 44682 | O22: 11.01 | P22: =(O22-O21)/O21 -> -0.02393617 | R22: 44682 | S22: 3.88 | T22: =(S22-S21)/S21 -> -0.03960396 | V22: 44682 | W22: 5.75 | X22: =(W22-W21)/W21 -> -0.022108844 | Z22: 44682 | AA22: 104.36 | AB22: =(AA22-AA21)/AA21 -> 0.0046207162 | AD22: 44682 | AE22: 1.89 | AF22: =(AE22-AE21)/AE21 -> -0.073529412
A23: 17 | B23: 44713 | C23: 42.25 | D23: =(C23-C22)/C22 -> 0.0028483266 | F23: 44713 | G23: 269.06 | H23: =(G23-G22)/G22 -> -0.010190192 | J23: 44713 | K23: 76.96 | L23: =(K23-K22)/K22 -> -0.13808937 | N23: 44713 | O23: 10.64 | P23: =(O23-O22)/O22 -> -0.033605813 | R23: 44713 | S23: 3.85 | T23: =(S23-S22)/S22 -> -0.0077319588 | V23: 44713 | W23: 5.97 | X23: =(W23-W22)/W22 -> 0.03826087 | Z23: 44713 | AA23: 90.38 | AB23: =(AA23-AA22)/AA22 -> -0.13395937 | AD23: 44713 | AE23: 1.51 | AF23: =(AE23-AE22)/AE22 -> -0.2010582
A24: 18 | B24: 44743 | C24: 49.54 | D24: =(C24-C23)/C23 -> 0.17254438 | F24: 44743 | G24: 289.84 | H24: =(G24-G23)/G23 -> 0.077231844 | J24: 44743 | K24: 92.99 | L24: =(K24-K23)/K23 -> 0.20829002 | N24: 44743 | O24: 11.78 | P24: =(O24-O23)/O23 -> 0.10714286 | R24: 44743 | S24: 3.89 | T24: =(S24-S23)/S23 -> 0.01038961 | V24: 44743 | W24: 6.34 | X24: =(W24-W23)/W23 -> 0.061976549 | Z24: 44743 | AA24: 100.77 | AB24: =(AA24-AA23)/AA23 -> 0.11495906 | AD24: 44743 | AE24: 1.89 | AF24: =(AE24-AE23)/AE23 -> 0.25165563
A25: 19 | B25: 44774 | C25: 54.48 | D25: =(C25-C24)/C24 -> 0.0997174 | F25: 44774 | G25: 293.54 | H25: =(G25-G24)/G24 -> 0.012765664 | J25: 44774 | K25: 87.75 | L25: =(K25-K24)/K24 -> -0.056350145 | N25: 44774 | O25: 10.49 | P25: =(O25-O24)/O24 -> -0.10950764 | R25: 44774 | S25: 3.97 | T25: =(S25-S24)/S24 -> 0.020565553 | V25: 44774 | W25: 5.35 | X25: =(W25-W24)/W24 -> -0.15615142 | Z25: 44774 | AA25: 97.47 | AB25: =(AA25-AA24)/AA24 -> -0.032747842 | AD25: 44774 | AE25: 1.92 | AF25: =(AE25-AE24)/AE24 -> 0.015873016
A26: 20 | B26: 44805 | C26: 50.19 | D26: =(C26-C25)/C25 -> -0.078744493 | F26: 44805 | G26: 285.02 | H26: =(G26-G25)/G25 -> -0.029025005 | J26: 44805 | K26: 73.51 | L26: =(K26-K25)/K25 -> -0.1622792 | N26: 44805 | O26: 8.82 | P26: =(O26-O25)/O25 -> -0.15919924 | R26: 44805 | S26: 3.85 | T26: =(S26-S25)/S25 -> -0.0302267 | V26: 44805 | W26: 4.85 | X26: =(W26-W25)/W25 -> -0.093457944 | Z26: 44805 | AA26: 90.7 | AB26: =(AA26-AA25)/AA25 -> -0.069457269 | AD26: 44805 | AE26: 1.605 | AF26: =(AE26-AE25)/AE25 -> -0.1640625
A27: 21 | B27: 44835 | C27: 55.82 | D27: =(C27-C26)/C26 -> 0.11217374 | F27: 44835 | G27: 280.48 | H27: =(G27-G26)/G26 -> -0.015928707 | J27: 44835 | K27: 78.07 | L27: =(K27-K26)/K26 -> 0.062032377 | N27: 44835 | O27: 8.32 | P27: =(O27-O26)/O26 -> -0.056689342 | R27: 44835 | S27: 3.92 | T27: =(S27-S26)/S26 -> 0.018181818 | V27: 44835 | W27: 4.9 | X27: =(W27-W26)/W26 -> 0.010309278 | Z27: 44835 | AA27: 104.68 | AB27: =(AA27-AA26)/AA26 -> 0.15413451 | AD27: 44835 | AE27: 1.68 | AF27: =(AE27-AE26)/AE26 -> 0.046728972
A28: 22 | B28: 44866 | C28: 59.44 | D28: =(C28-C27)/C27 -> 0.064851308 | F28: 44866 | G28: 300.11 | H28: =(G28-G27)/G27 -> 0.069987165 | J28: 44866 | K28: 70.64 | L28: =(K28-K27)/K27 -> -0.095171 | N28: 44866 | O28: 9.87 | P28: =(O28-O27)/O27 -> 0.18629808 | R28: 44866 | S28: 3.98 | T28: =(S28-S27)/S27 -> 0.015306122 | V28: 44866 | W28: 4.89 | X28: =(W28-W27)/W27 -> -0.0020408163 | Z28: 44866 | AA28: 107.86 | AB28: =(AA28-AA27)/AA27 -> 0.030378296 | AD28: 44866 | AE28: 1.665 | AF28: =(AE28-AE27)/AE27 -> -0.0089285714
A29: 23 | B29: 44896 | C29: 55.26 | D29: =(C29-C28)/C28 -> -0.070323015 | F29: 44896 | G29: 287.76 | H29: =(G29-G28)/G28 -> -0.041151578 | J29: 44896 | K29: 70.27 | L29: =(K29-K28)/K28 -> -0.0052378256 | N29: 44896 | O29: 9.1 | P29: =(O29-O28)/O28 -> -0.078014184 | R29: 44896 | S29: 3.99 | T29: =(S29-S28)/S28 -> 0.0025125628 | V29: 44896 | W29: 4.89 | X29: =(W29-W28)/W28 -> 0 | Z29: 44896 | AA29: 102.6 | AB29: =(AA29-AA28)/AA28 -> -0.04876692 | AD29: 44896 | AE29: 1.455 | AF29: =(AE29-AE28)/AE28 -> -0.12612613
... A54: 48 | B54: 45658 | C54: 278.4 | D54: =(C54-C53)/C53 -> 0.11306573 | F54: 45658 | G54: 280.43 | H54: =(G54-G53)/G53 -> -0.0040840969 | J54: 45658 | K54: 183.27 | L54: =(K54-K53)/K53 -> 0.087268628 | N54: 45658 | O54: 14.85 | P54: =(O54-O53)/O53 -> -0.01459854 | R54: 45658 | S54: 3.95 | T54: =(S54-S53)/S53 -> -0.014962594 | V54: 45658 | W54: 4.4 | X54: =(W54-W53)/W53 -> -0.020044543 | Z54: 45658 | AA54: 160.56 | AB54: =(AA54-AA53)/AA53 -> 0.047699837 | AD54: 45658 | AE54: 1.65 | AF54: =(AE54-AE53)/AE53 -> 0.092715232
D55: =AVERAGE(D7:D54) -> 0.045530186 | H55: =AVERAGE(H7:H54) -> 0.0018673008 | L55: =AVERAGE(L7:L54) -> 0.011564818 | P55: =AVERAGE(P7:P54) -> 0.0084991829 | T55: =AVERAGE(T7:T54) -> 0.0055431375 | X55: =AVERAGE(X7:X54) -> -0.0082112647 | AB55: =AVERAGE(AB7:AB54) -> 0.015632543 | AF55: =AVERAGE(AF7:AF54) -> -0.0062336918

Sheet 1.b Sample  (Return and Risk)
C2: Table 1.b.1
B3: Monthly rate of return | C3: S11 | D3: S12 | E3: S21 | F3: S22 | G3: S31 | H3: S32 | I3: S41 | J3: S42
C4: 1 | D4: 2 | E4: 3 | F4: 4 | G4: 5 | H4: 6 | I4: 7 | J4: 8 | N4: Table 1.b.2
B5: Date | C5: Monthly rate of return of Pro Medicus Limited | D5: Monthly return of CSL Limited | E5: Monthly rate of return of Xero Limited | F5: Monthly return of NEXTDC Limited | G5: Monthly rate of return of Telstra Group Limited | H5: Monthly retun of TPG Telecom Limited | I5: Monthly rate of return of Commonwealth Bank | J5: Monthly return of Australian Finance Group Limited | M5: Symbol | N5: Company | O5: Category | P5: Category code | Q5: Category sub code for chosen assests | R5: Average 4 year return | S5: Stnd Deviation of 4 years | T5: Risk Category (R1 / R2 /R3)
B6: Code | C6: (ASX.PME) | D6: (ASX.CSL) | E6: (ASX:XRO) | F6: (ASX.NXT) | G6: (ASX:TLS) | H6: (ASX.TPG) | I6: (ASX:CBA) | J6: (ASX.AFG) | M6: (ASX:PME) | N6: Pro Medicus Limited | O6: Healthcare | P6: S1 | Q6: S11 | R6: =C56 -> 0.045530186 | S6: =C57 -> 0.10936386 | T6: R3
A7: 0 | B7: 44197 | M7: (ASX.CSL) | N7: CSL Limited | Q7: S12 | R7: =D56 -> 0.0018673008 | S7: =D57 -> 0.049762204 | T7: R1
A8: 1 | B8: 44228 | C8: ='1.a Compute rate of return'!D7 -> 0.035247432 | D8: ='1.a Compute rate of return'!H7 -> -0.033600765 | E8: ='1.a Compute rate of return'!L7 -> -0.088228501 | F8: ='1.a Compute rate of return'!P7 -> -0.034482759 | G8: ='1.a Compute rate of return'!T7 -> -0.012820513 | H8: ='1.a Compute rate of return'!X7 -> -0.081081081 | I8: ='1.a Compute rate of return'!AB7 -> -0.023350497 | J8: ='1.a Compute rate of return'!AF7 -> 0.025547445 | M8: (ASX:XRO) | N8: Xero Limited | O8: Technology | P8: S2 | Q8: S21 | R8: =E56 -> 0.011564818 | S8: =E57 -> 0.094151229 | T8: R3
A9: 2 | B9: 44256 | C9: ='1.a Compute rate of return'!D8 -> -0.068094701 | D9: ='1.a Compute rate of return'!H8 -> 0.0078449294 | E9: ='1.a Compute rate of return'!L8 -> 0.068394832 | F9: ='1.a Compute rate of return'!P8 -> -0.069642857 | G9: ='1.a Compute rate of return'!T8 -> 0.1038961 | H9: ='1.a Compute rate of return'!X8 -> -0.069117647 | I9: ='1.a Compute rate of return'!AB8 -> 0.055664541 | J9: ='1.a Compute rate of return'!AF8 -> -0.06405694 | M9: (ASX.NXT) | N9: NEXTDC Limited | Q9: S22 | R9: =F56 -> 0.0084991829 | S9: =F57 -> 0.083522881 | T9: R2
A10: 3 | B10: 44287 | C10: ='1.a Compute rate of return'!D9 -> 0.14226954 | D10: ='1.a Compute rate of return'!H9 -> 0.024598526 | E10: ='1.a Compute rate of return'!L9 -> 0.11878606 | F10: ='1.a Compute rate of return'!P9 -> 0.11228407 | G10: ='1.a Compute rate of return'!T9 -> -0.0029411765 | H10: ='1.a Compute rate of return'!X9 -> -0.12954186 | I10: ='1.a Compute rate of return'!AB9 -> 0.034146341 | J10: ='1.a Compute rate of return'!AF9 -> 0.072243346 | M10: (ASX:TLS) | N10: Telstra Group Limited | O10: Communication services | P10: S3 | Q10: S31 | R10: =G56 -> 0.0055431375 | S10: =G57 -> 0.035698466 | T10: R1
A11: 4 | B11: 44317 | C11: ='1.a Compute rate of return'!D10 -> -0.023300148 | D11: ='1.a Compute rate of return'!H10 -> 0.070253725 | E11: ='1.a Compute rate of return'!L10 -> -0.062941509 | F11: ='1.a Compute rate of return'!P10 -> -0.061259707 | G11: ='1.a Compute rate of return'!T10 -> 0.038348083 | H11: ='1.a Compute rate of return'!X10 -> -0.054446461 | I11: ='1.a Compute rate of return'!AB10 -> 0.11994609 | J11: ='1.a Compute rate of return'!AF10 -> 0 | M11: (ASX.TPG) | N11: TPG Telecom Limited | Q11: S32 | R11: =H56 -> -0.0082112647 | S11: =H57 -> 0.07254004 | T11: R2
A12: 5 | B12: 44348 | C12: ='1.a Compute rate of return'!D11 -> 0.27347647 | D12: ='1.a Compute rate of return'!H11 -> -0.017297819 | E12: ='1.a Compute rate of return'!L11 -> 0.033546928 | F12: ='1.a Compute rate of return'!P11 -> 0.090073529 | G12: ='1.a Compute rate of return'!T11 -> 0.068181818 | H12: ='1.a Compute rate of return'!X11 -> 0.20153551 | I12: ='1.a Compute rate of return'!AB11 -> 0.0015042118 | J12: ='1.a Compute rate of return'!AF11 -> 0.010638298 | M12: (ASX:CBA) | N12: Commonwealth Bank | O12: Financial Services | P12: S4 | Q12: S41 | R12: =I56 -> 0.015632543 | S12: =I57 -> 0.062967476 | T12: R2
A13: 6 | B13: 44378 | C13: ='1.a Compute rate of return'!D12 -> -0.01260218 | D13: ='1.a Compute rate of return'!H12 -> 0.013043936 | E13: ='1.a Compute rate of return'!L12 -> 0.023194748 | F13: ='1.a Compute rate of return'!P12 -> 0.075042159 | G13: ='1.a Compute rate of return'!T12 -> 0.0053191489 | H13: ='1.a Compute rate of return'!X12 -> -0.012779553 | I13: ='1.a Compute rate of return'!AB12 -> -0.0022028637 | J13: ='1.a Compute rate of return'!AF12 -> -0.09122807 | M13: (ASX.AFG) | N13: Australian Finance Group Limited | Q13: S42 | R13: =J56 -> -0.0062336918 | S13: =J57 -> 0.093580805 | T13: R3
A14: 7 | B14: 44409 | C14: ='1.a Compute rate of return'!D13 -> 0.087788893 | D14: ='1.a Compute rate of return'!H13 -> 0.079713406 | E14: ='1.a Compute rate of return'!L13 -> 0.082264043 | F14: ='1.a Compute rate of return'!P13 -> 0.038431373 | G14: ='1.a Compute rate of return'!T13 -> 0.015873016 | H14: ='1.a Compute rate of return'!X13 -> -0.003236246 | I14: ='1.a Compute rate of return'!AB13 -> 0.0047165078 | J14: ='1.a Compute rate of return'!AF13 -> 0.16988417
A15: 8 | B15: 44440 | C15: ='1.a Compute rate of return'!D14 -> -0.13413667 | D15: ='1.a Compute rate of return'!H14 -> -0.059434507 | E15: ='1.a Compute rate of return'!L14 -> -0.084442102 | F15: ='1.a Compute rate of return'!P14 -> -0.091389728 | G15: ='1.a Compute rate of return'!T14 -> 0.0234375 | H15: ='1.a Compute rate of return'!X14 -> 0.1461039 | I15: ='1.a Compute rate of return'!AB14 -> 0.042049541 | J15: ='1.a Compute rate of return'!AF14 -> -0.085808581
A16: 9 | B16: 44470 | C16: ='1.a Compute rate of return'!D15 -> -0.024354514 | D16: ='1.a Compute rate of return'!H15 -> 0.024164963 | E16: ='1.a Compute rate of return'!L15 -> 0.075611511 | F16: ='1.a Compute rate of return'!P15 -> -0.024106401 | G16: ='1.a Compute rate of return'!T15 -> -0.027989822 | H16: ='1.a Compute rate of return'!X15 -> -0.043909348 | I16: ='1.a Compute rate of return'!AB15 -> 0.0033547398 | J16: ='1.a Compute rate of return'!AF15 -> -0.050541516 | N16: Table 1.b.3
A17: 10 | B17: 44501 | C17: ='1.a Compute rate of return'!D16 -> 0.17267267 | D17: ='1.a Compute rate of return'!H16 -> 0.020965756 | E17: ='1.a Compute rate of return'!L16 -> -0.031235369 | F17: ='1.a Compute rate of return'!P16 -> 0.030664395 | G17: ='1.a Compute rate of return'!T16 -> 0.065445026 | H17: ='1.a Compute rate of return'!X16 -> 0 | I17: ='1.a Compute rate of return'!AB16 -> -0.10985862 | J17: ='1.a Compute rate of return'!AF16 -> 0.02661597 | N17: Health Care S1 | P17: Technology S2 | R17: Communi. Services S3 | T17: Financial. Ser S4
A18: 11 | B18: 44531 | C18: ='1.a Compute rate of return'!D17 -> -0.00064020487 | D18: ='1.a Compute rate of return'!H17 -> -0.052381108 | E18: ='1.a Compute rate of return'!L17 -> -0.023474178 | F18: ='1.a Compute rate of return'!P17 -> 0.057024793 | G18: ='1.a Compute rate of return'!T17 -> 0.027027027 | H18: ='1.a Compute rate of return'!X17 -> -0.12740741 | I18: ='1.a Compute rate of return'!AB17 -> 0.083923589 | J18: ='1.a Compute rate of return'!AF17 -> 0 | N18: S11 | O18: S12 | P18: S21 | Q18: S22 | R18: S31 | S18: S32 | T18: S41 | U18: S42 | V18: Total
A19: 12 | B19: 44562 | C19: ='1.a Compute rate of return'!D18 -> -0.2777066 | D19: ='1.a Compute rate of return'!H18 -> -0.10446478 | E19: ='1.a Compute rate of return'!L18 -> -0.20171097 | F19: ='1.a Compute rate of return'!P18 -> -0.1657545 | G19: ='1.a Compute rate of return'!T18 -> -0.062200957 | H19: ='1.a Compute rate of return'!X18 -> 0.0016977929 | I19: ='1.a Compute rate of return'!AB18 -> -0.071881188 | J19: ='1.a Compute rate of return'!AF18 -> -0.18518519 | M19: R1 | O19: CSL Limited | R19: Telstra Group Limited | V19: at least two investments
A20: 13 | B20: 44593 | C20: ='1.a Compute rate of return'!D19 -> 0.036141907 | D20: ='1.a Compute rate of return'!H19 -> -0.0014211638 | E20: ='1.a Compute rate of return'!L19 -> -0.16986981 | F20: ='1.a Compute rate of return'!P19 -> -0.0037488285 | G20: ='1.a Compute rate of return'!T19 -> 0.010204082 | H20: ='1.a Compute rate of return'!X19 -> -0.052542373 | I20: ='1.a Compute rate of return'!AB19 -> -0.0029869853 | J20: ='1.a Compute rate of return'!AF19 -> 0.0045454545 | M20: R2 | Q20: NEXTDC Limited | S20: TPG Telecom Limited | T20: Commonwealth Bank | V20: at least two investments
A21: 14 | B21: 44621 | C21: ='1.a Compute rate of return'!D20 -> 0.048362936 | D21: ='1.a Compute rate of return'!H20 -> 0.031425494 | E21: ='1.a Compute rate of return'!L20 -> 0.096233863 | F21: ='1.a Compute rate of return'!P20 -> 0.096895579 | G21: ='1.a Compute rate of return'!T20 -> 0 | H21: ='1.a Compute rate of return'!X20 -> 0.082289803 | I21: ='1.a Compute rate of return'!AB20 -> 0.1317141 | J21: ='1.a Compute rate of return'!AF20 -> -0.027149321 | M21: R3 | N21: Pro Medicus Limited | P21: Xero Limited | U21: Australian Finance Group Limited | V21: at least two investments
A22: 15 | B22: 44652 | C22: ='1.a Compute rate of return'!D21 -> -0.030822617 | D22: ='1.a Compute rate of return'!H21 -> 0.019205668 | E22: ='1.a Compute rate of return'!L21 -> -0.062287105 | F22: ='1.a Compute rate of return'!P21 -> -0.032590051 | G22: ='1.a Compute rate of return'!T21 -> 0.02020202 | H22: ='1.a Compute rate of return'!X21 -> -0.028099174 | I22: ='1.a Compute rate of return'!AB21 -> -0.017868961 | J22: ='1.a Compute rate of return'!AF21 -> -0.051162791
A23: 16 | B23: 44682 | C23: ='1.a Compute rate of return'!D22 -> -0.11267902 | D23: ='1.a Compute rate of return'!H22 -> -0.0053787047 | E23: ='1.a Compute rate of return'!L22 -> -0.07327452 | F23: ='1.a Compute rate of return'!P22 -> -0.02393617 | G23: ='1.a Compute rate of return'!T22 -> -0.03960396 | H23: ='1.a Compute rate of return'!X22 -> -0.022108844 | I23: ='1.a Compute rate of return'!AB22 -> 0.0046207162 | J23: ='1.a Compute rate of return'!AF22 -> -0.073529412
A24: 17 | B24: 44713 | C24: ='1.a Compute rate of return'!D23 -> 0.0028483266 | D24: ='1.a Compute rate of return'!H23 -> -0.010190192 | E24: ='1.a Compute rate of return'!L23 -> -0.13808937 | F24: ='1.a Compute rate of return'!P23 -> -0.033605813 | G24: ='1.a Compute rate of return'!T23 -> -0.0077319588 | H24: ='1.a Compute rate of return'!X23 -> 0.03826087 | I24: ='1.a Compute rate of return'!AB23 -> -0.13395937 | J24: ='1.a Compute rate of return'!AF23 -> -0.2010582
A25: 18 | B25: 44743 | C25: ='1.a Compute rate of return'!D24 -> 0.17254438 | D25: ='1.a Compute rate of return'!H24 -> 0.077231844 | E25: ='1.a Compute rate of return'!L24 -> 0.20829002 | F25: ='1.a Compute rate of return'!P24 -> 0.10714286 | G25: ='1.a Compute rate of return'!T24 -> 0.01038961 | H25: ='1.a Compute rate of return'!X24 -> 0.061976549 | I25: ='1.a Compute rate of return'!AB24 -> 0.11495906 | J25: ='1.a Compute rate of return'!AF24 -> 0.25165563
A26: 19 | B26: 44774 | C26: ='1.a Compute rate of return'!D25 -> 0.0997174 | D26: ='1.a Compute rate of return'!H25 -> 0.012765664 | E26: ='1.a Compute rate of return'!L25 -> -0.056350145 | F26: ='1.a Compute rate of return'!P25 -> -0.10950764 | G26: ='1.a Compute rate of return'!T25 -> 0.020565553 | H26: ='1.a Compute rate of return'!X25 -> -0.15615142 | I26: ='1.a Compute rate of return'!AB25 -> -0.032747842 | J26: ='1.a Compute rate of return'!AF25 -> 0.015873016
A27: 20 | B27: 44805 | C27: ='1.a Compute rate of return'!D26 -> -0.078744493 | D27: ='1.a Compute rate of return'!H26 -> -0.029025005 | E27: ='1.a Compute rate of return'!L26 -> -0.1622792 | F27: ='1.a Compute rate of return'!P26 -> -0.15919924 | G27: ='1.a Compute rate of return'!T26 -> -0.0302267 | H27: ='1.a Compute rate of return'!X26 -> -0.093457944 | I27: ='1.a Compute rate of return'!AB26 -> -0.069457269 | J27: ='1.a Compute rate of return'!AF26 -> -0.1640625
A28: 21 | B28: 44835 | C28: ='1.a Compute rate of return'!D27 -> 0.11217374 | D28: ='1.a Compute rate of return'!H27 -> -0.015928707 | E28: ='1.a Compute rate of return'!L27 -> 0.062032377 | F28: ='1.a Compute rate of return'!P27 -> -0.056689342 | G28: ='1.a Compute rate of return'!T27 -> 0.018181818 | H28: ='1.a Compute rate of return'!X27 -> 0.010309278 | I28: ='1.a Compute rate of return'!AB27 -> 0.15413451 | J28: ='1.a Compute rate of return'!AF27 -> 0.046728972
A29: 22 | B29: 44866 | C29: ='1.a Compute rate of return'!D28 -> 0.064851308 | D29: ='1.a Compute rate of return'!H28 -> 0.069987165 | E29: ='1.a Compute rate of return'!L28 -> -0.095171 | F29: ='1.a Compute rate of return'!P28 -> 0.18629808 | G29: ='1.a Compute rate of return'!T28 -> 0.015306122 | H29: ='1.a Compute rate of return'!X28 -> -0.0020408163 | I29: ='1.a Compute rate of return'!AB28 -> 0.030378296 | J29: ='1.a Compute rate of return'!AF28 -> -0.0089285714
A30: 23 | B30: 44896 | C30: ='1.a Compute rate of return'!D29 -> -0.070323015 | D30: ='1.a Compute rate of return'!H29 -> -0.041151578 | E30: ='1.a Compute rate of return'!L29 -> -0.0052378256 | F30: ='1.a Compute rate of return'!P29 -> -0.078014184 | G30: ='1.a Compute rate of return'!T29 -> 0.0025125628 | H30: ='1.a Compute rate of return'!X29 -> 0 | I30: ='1.a Compute rate of return'!AB29 -> -0.04876692 | J30: ='1.a Compute rate of return'!AF29 -> -0.12612613
A31: 24 | B31: 44927 | C31: ='1.a Compute rate of return'!D30 -> 0.20973579 | D31: ='1.a Compute rate of return'!H30 -> 0.035863219 | E31: ='1.a Compute rate of return'!L30 -> 0.09292728 | F31: ='1.a Compute rate of return'!P30 -> 0.086813187 | G31: ='1.a Compute rate of return'!T30 -> 0.022556391 | H31: ='1.a Compute rate of return'!X30 -> -0.014314928 | I31: ='1.a Compute rate of return'!AB30 -> 0.072709552 | J31: ='1.a Compute rate of return'!AF30 -> 0.16151203
A32: 25 | B32: 44958 | C32: ='1.a Compute rate of return'!D31 -> -0.087359761 | D32: ='1.a Compute rate of return'!H31 -> -0.0059715513 | E32: ='1.a Compute rate of return'!L31 -> 0.01171875 | F32: ='1.a Compute rate of return'!P31 -> 0.038422649 | G32: ='1.a Compute rate of return'!T31 -> 0.019607843 | H32: ='1.a Compute rate of return'!X31 -> 0.05186722 | I32: ='1.a Compute rate of return'!AB31 -> -0.085135381 | J32: ='1.a Compute rate of return'!AF31 -> -0.068047337
A33: 26 | B33: 44986 | C33: ='1.a Compute rate of return'!D32 -> 0.046877561 | D33: ='1.a Compute rate of return'!H32 -> -0.026999663 | E33: ='1.a Compute rate of return'!L32 -> 0.15083655 | F33: ='1.a Compute rate of return'!P32 -> 0.018500487 | G33: ='1.a Compute rate of return'!T32 -> 0.014423077 | H33: ='1.a Compute rate of return'!X32 -> -0.037475345 | I33: ='1.a Compute rate of return'!AB32 -> -0.023537591 | J33: ='1.a Compute rate of return'!AF32 -> -0.053968254
... A55: 48 | B55: 45658 | C55: ='1.a Compute rate of return'!D54 -> 0.11306573 | D55: ='1.a Compute rate of return'!H54 -> -0.0040840969 | E55: ='1.a Compute rate of return'!L54 -> 0.087268628 | F55: ='1.a Compute rate of return'!P54 -> -0.01459854 | G55: ='1.a Compute rate of return'!T54 -> -0.014962594 | H55: ='1.a Compute rate of return'!X54 -> -0.020044543 | I55: ='1.a Compute rate of return'!AB54 -> 0.047699837 | J55: ='1.a Compute rate of return'!AF54 -> 0.092715232
B56: Ave. Annual Return Rate (48 mths) | C56: =AVERAGE(C8:C55) -> 0.045530186 | D56: =AVERAGE(D8:D55) -> 0.0018673008 | E56: =AVERAGE(E8:E55) -> 0.011564818 | F56: =AVERAGE(F8:F55) -> 0.0084991829 | G56: =AVERAGE(G8:G55) -> 0.0055431375 | H56: =AVERAGE(H8:H55) -> -0.0082112647 | I56: =AVERAGE(I8:I55) -> 0.015632543 | J56: =AVERAGE(J8:J55) -> -0.0062336918
B57: Std Deviation | C57: =_xlfn.STDEV.S(C8:C55) -> 0.10936386 | D57: =_xlfn.STDEV.S(D8:D55) -> 0.049762204 | E57: =_xlfn.STDEV.S(E8:E55) -> 0.094151229 | F57: =_xlfn.STDEV.S(F8:F55) -> 0.083522881 | G57: =_xlfn.STDEV.S(G8:G55) -> 0.035698466 | H57: =_xlfn.STDEV.S(H8:H55) -> 0.07254004 | I57: =_xlfn.STDEV.S(I8:I55) -> 0.062967476 | J57: =_xlfn.STDEV.S(J8:J55) -> 0.093580805
C58: C1 | D58: C1 | E58: C2 | F58: C2 | G58: C3 | H58: C3 | I58: C4 | J58: C4
C59: R3 | D59: R1 | E59: R3 | F59: R2 | G59: R1 | H59: R2 | I59: R2 | J59: R3
C61: Min | D61: Max
C62: 0.01 | D62: 0.0499 | E62: <= | F62: R1
C63: 0.05 | D63: 0.0899 | E63: <= | F63: R2
...

Sheet 2.a. LP Modelling 
C2: LP model
C4: DECISION VARIABLES
C5: Risk | D5: R3 | E5: R1 | F5: R3 | G5: R2 | H5: R1 | I5: R2 | J5: R2 | K5: R3
C6: Sector | D6: S11 | E6: S12 | F6: S21 | G6: S22 | H6: S31 | I6: S32 | J6: S41 | K6: S42
C7: Allocation Proportion per asset | D7: 0.05 | E7: 0.1 | F7: 0.05 | G7: 0.1 | H7: 0.4 | I7: 0.05 | J7: 0.2 | K7: 0.05
C10: OBJECTIVE FUNCTION
C11: Risk | D11: R3 | E11: R1 | F11: R3 | G11: R2 | H11: R1 | I11: R2 | J11: R2 | K11: R3
C12: Sector | D12: S11 | E12: S12 | F12: S21 | G12: S22 | H12: S31 | I12: S32 | J12: S41 | K12: S42
C13: Annual Average rate of Return | D13: 0.0455 | E13: 0.0019 | F13: 0.0116 | G13: 0.0085 | H13: 0.0055 | I13: -0.0082 | J13: 0.0156 | K13: -0.0062
C15: Expected Return | D15: =SUMPRODUCT(D7:K7,D13:K13) -> 0.008495
C18: CONSTRAINTS | D18: R3 | E18: R1 | F18: R3 | G18: R2 | H18: R1 | I18: R2 | J18: R2 | K18: R3 | L18: LHS | M18: Symbol | N18: RHS
D19: S11 | E19: S12 | F19: S21 | G19: S22 | H19: S31 | I19: S32 | J19: S41 | K19: S42 | M19: Function
D20: X1 | E20: X2 | F20: X3 | G20: X4 | H20: X5 | I20: X6 | J20: X7 | K20: X8
B21: 1) | C21: The total investment in high-risk assets (R3) must not exceed 15% of the overall portfolio. | D21: 1 | E21: 0 | F21: 1 | G21: 0 | H21: 0 | I21: 0 | J21: 0 | K21: 1 | L21: =SUMPRODUCT(D21:K21,$D7:$K7) -> 0.15 | M21: <= | N21: 0.15
B22: 2) | C22: The total of R1 should be greater than or equal to R2 and R3 asset categories | D22: 0 | E22: 1 | F22: 0 | G22: 0 | H22: 1 | I22: 0 | J22: 0 | K22: 0 | L22: =SUMPRODUCT(D22:K22,$D7:$K7) -> 0.5 | M22: >= | N22: 0.5
A23: 3) | B23: 3 a) | C23: Minimum investment for sector S1 (Healthcare) should be greater than or equal to 15% | D23: 1 | E23: 1 | F23: 0 | G23: 0 | H23: 0 | I23: 0 | J23: 0 | K23: 0 | L23: =SUMPRODUCT(D23:K23,$D7:$K7) -> 0.15 | M23: >= | N23: 0.15
B24: 3 b) | C24: Minimum investment for sector S2 (Technology) should be greater than or equal to 15% | D24: 0 | E24: 0 | F24: 1 | G24: 1 | H24: 0 | I24: 0 | J24: 0 | K24: 0 | L24: =SUMPRODUCT(D24:K24,$D7:$K7) -> 0.15 | M24: >= | N24: 0.15
B25: 3 c) | C25: Minimum investment for sector S3 (Communication Services) should be greater than or equal to 15% | D25: 0 | E25: 0 | F25: 0 | G25: 0 | H25: 1 | I25: 1 | J25: 0 | K25: 0 | L25: =SUMPRODUCT(D25:K25,$D7:$K7) -> 0.45 | M25: >= | N25: 0.15
B26: 3 d) | C26: Minimum investment for sector S4 (Financials) should be greater than or equal to 20% | D26: 0 | E26: 0 | F26: 0 | G26: 0 | H26: 0 | I26: 0 | J26: 1 | K26: 1 | L26: =SUMPRODUCT(D26:K26,$D7:$K7) -> 0.25 | M26: >= | N26: 0.2
A27: 4) | B27: 4a) | C27: Minimum investment for S11 | D27: 1 | E27: 0 | F27: 0 | G27: 0 | H27: 0 | I27: 0 | J27: 0 | K27: 0 | L27: =SUMPRODUCT(D27:K27,$D7:$K7) -> 0.05 | M27: >= | N27: 0.05
B28: 4b) | C28: Minimum investment for S12 | D28: 0 | E28: 1 | F28: 0 | G28: 0 | H28: 0 | I28: 0 | J28: 0 | K28: 0 | L28: =SUMPRODUCT(D28:K28,$D7:$K7) -> 0.1 | M28: >= | N28: 0.05
B29: 4c) | C29: Minimum investment for S21 | D29: 0 | E29: 0 | F29: 1 | G29: 0 | H29: 0 | I29: 0 | J29: 0 | K29: 0 | L29: =SUMPRODUCT(D29:K29,$D7:$K7) -> 0.05 | M29: >= | N29: 0.05
B30: 4d) | C30: Minimum investment for S22 | D30: 0 | E30: 0 | F30: 0 | G30: 1 | H30: 0 | I30: 0 | J30: 0 | K30: 0 | L30: =SUMPRODUCT(D30:K30,$D7:$K7) -> 0.1 | M30: >= | N30: 0.05
B31: 4e) | C31: Minimum investment for S31 | D31: 0 | E31: 0 | F31: 0 | G31: 0 | H31: 1 | I31: 0 | J31: 0 | K31: 0 | L31: =SUMPRODUCT(D31:K31,$D7:$K7) -> 0.4 | M31: >= | N31: 0.05
B32: 4f) | C32: Minimum investment for S32 | D32: 0 | E32: 0 | F32: 0 | G32: 0 | H32: 0 | I32: 1 | J32: 0 | K32: 0 | L32: =SUMPRODUCT(D32:K32,$D7:$K7) -> 0.05 | M32: >= | N32: 0.05
B33: 4g) | C33: Minimum investment for S41 | D33: 0 | E33: 0 | F33: 0 | G33: 0 | H33: 0 | I33: 0 | J33: 1 | K33: 0 | L33: =SUMPRODUCT(D33:K33,$D7:$K7) -> 0.2 | M33: >= | N33: 0.05
B34: 4h) | C34: Minimum investment for S42 | D34: 0 | E34: 0 | F34: 0 | G34: 0 | H34: 0 | I34: 0 | J34: 0 | K34: 1 | L34: =SUMPRODUCT(D34:K34,$D7:$K7) -> 0.05 | M34: >= | N34: 0.05
B35: 5) | C35: Investment in medium-risk assets (R2) must be at least 25% of the portfolio | D35: 0 | E35: 0 | F35: 0 | G35: 1 | H35: 0 | I35: 1 | J35: 1 | K35: 0 | L35: =SUMPRODUCT(D35:K35,$D7:$K7) -> 0.35 | M35: >= | N35: 0.25
B36: 6) | C36: The sum of all 8 investments must add up to exactly 100% of the portfolio. | D36: 1 | E36: 1 | F36: 1 | G36: 1 | H36: 1 | I36: 1 | J36: 1 | K36: 1 | L36: =SUMPRODUCT(D36:K36,$D7:$K7) -> 1 | M36: = | N36: 1

Sheet 2.b LP Sensitivity Report 1
A1: Microsoft Excel 16.0 Sensitivity Report
A2: Worksheet: [Jayendra A1 Worksheet.xlsx]2.a. LP Modelling
A3: Report Created: 8/04/2025 1:23:04 AM
A6: Variable Cells
D7: Final | E7: Reduced | F7: Objective | G7: Allowable | H7: Allowable
B8: Cell | C8: Name | D8: Value | E8: Cost | F8: Coefficient | G8: Increase | H8: Decrease
B9: $D$5 | C9: S11 | D9: 0.05 | E9: 0 | F9: 0.0455 | G9: 1e+30 | H9: 0.0304
B10: $E$5 | C10: S12 | D10: 0.1 | E10: 0 | F10: 0.0019 | G10: 0.0036 | H10: 1e+30
B11: $F$5 | C11: S21 | D11: 0.05 | E11: 0 | F11: 0.0116 | G11: 0.0304 | H11: 1e+30
B12: $G$5 | C12: S22 | D12: 0.1 | E12: 0 | F12: 0.0085 | G12: 0.0071 | H12: 0.0304
B13: $H$5 | C13: S31 | D13: 0.4 | E13: 0 | F13: 0.0055 | G13: 0.0101 | H13: 0.0036
B14: $I$5 | C14: S32 | D14: 0.05 | E14: 0 | F14: -0.0082 | G14: 0.0238 | H14: 1e+30
B15: $J$5 | C15: S41 | D15: 0.2 | E15: 0 | F15: 0.0156 | G15: 0.0304 | H15: 0.0071
B16: $K$5 | C16: S42 | D16: 0.05 | E16: 0 | F16: -0.0062 | G16: 0.0553 | H16: 1e+30
A18: Constraints
D19: Final | E19: Shadow | F19: Constraint | G19: Allowable | H19: Allowable
B20: Cell | C20: Name | D20: Value | E20: Price | F20: R.H. Side | G20: Increase | H20: Decrease
B21: $L$18 | C21: The total of R1 should be greater than or equal to R2 and R3 asset categories LHS | D21: 0.5 | E21: -0.0101 | F21: 0.5 | G21: 0.05 | H21: 0.3
B22: $L$17 | C22: The total investment in high-risk assets (R3) must not exceed 15% of the overall portfolio. LHS | D22: 0.15 | E22: 0.0335 | F22: 0.15 | G22: 0.05 | H22: 0
B23: $L$19 | C23: Sector S1 (Healthcare) ≥ 15% LHS | D23: 0.15 | E23: -0.0036 | F23: 0.15 | G23: 0.3 | H23: 0.05
B24: $L$20 | C24: Sector S2 (Technology) ≥ 15% LHS | D24: 0.15 | E24: -0.0071 | F24: 0.15 | G24: 0.05 | H24: 0.05
B25: $L$21 | C25: Sector S3 (Communication Services) ≥ 15% LHS | D25: 0.45 | E25: 0 | F25: 0.15 | G25: 0.3 | H25: 1e+30
B26: $L$22 | C26: Sector S4 (Financials) ≥ 20% LHS | D26: 0.25 | E26: 0 | F26: 0.2 | G26: 0.05 | H26: 1e+30
B27: $L$23 | C27: Min investment for S11 LHS | D27: 0.05 | E27: 0 | F27: 0.05 | G27: -1.3877788e-17 | H27: 1e+30
B28: $L$24 | C28: Min investment for S12 LHS | D28: 0.1 | E28: 0 | F28: 0.05 | G28: 0.05 | H28: 1e+30
B29: $L$25 | C29: Min investment for S21 LHS | D29: 0.05 | E29: -0.0304 | F29: 0.05 | G29: 0 | H29: 0.05
B30: $L$26 | C30: Min investment for S22 LHS | D30: 0.1 | E30: 0 | F30: 0.05 | G30: 0.05 | H30: 1e+30
B31: $L$27 | C31: Min investment for S31 LHS | D31: 0.4 | E31: 0 | F31: 0.05 | G31: 0.35 | H31: 1e+30
B32: $L$28 | C32: Min investment for S32 LHS | D32: 0.05 | E32: -0.0238 | F32: 0.05 | G32: 0.05 | H32: 0.05
... B36: $L$32 | C36: The sum of all 8 investments must add up to exactly 100% of the portfolio. LHS | D36: 1 | E36: 0.0156 | F36: 1 | G36: 1e+30 | H36: 0.05

Sheet 3.a ILP modelling
C2: ILP model
C4: DECISION VARIABLES
C5: Risk | D5: R3 | E5: R1 | F5: R3 | G5: R2 | H5: R1 | I5: R2 | J5: R2 | K5: R3
C6: Sector | D6: S11 | E6: S12 | F6: S21 | G6: S22 | H6: S31 | I6: S32 | J6: S41 | K6: S42
C7: Invest? (1= Yes, 0 = No) | D7: 1 | E7: 1 | F7: 0 | G7: 1 | H7: 1 | I7: 0 | J7: 1 | K7: 0
C10: OBJECTIVE FUNCTION
C11: Risk | D11: R3 | E11: R1 | F11: R3 | G11: R2 | H11: R1 | I11: R2 | J11: R2 | K11: R3
C12: Sector | D12: S11 | E12: S12 | F12: S21 | G12: S22 | H12: S31 | I12: S32 | J12: S41 | K12: S42
C13: Annual Average Rate of Return | D13: 0.0455 | E13: 0.0019 | F13: 0.0116 | G13: 0.0085 | H13: 0.0055 | I13: -0.0082 | J13: 0.0156 | K13: -0.0062
C15: Expected Return | D15: =SUMPRODUCT(D7:K7,D13:K13) -> 0.077
C18: CONSTRAINTS | D18: R3 | E18: R1 | F18: R3 | G18: R2 | H18: R1 | I18: R2 | J18: R2 | K18: R3 | L18: LHS | M18: Symbol | N18: RHS
D19: S11 | E19: S12 | F19: S21 | G19: S22 | H19: S31 | I19: S32 | J19: S41 | K19: S42 | M19: Function
D20: X1 | E20: X2 | F20: X3 | G20: X4 | H20: X5 | I20: X6 | J20: X7 | K20: X8
B21: 1) | C21: Balanced portfolio of 5 stocks | D21: 1 | E21: 1 | F21: 1 | G21: 1 | H21: 1 | I21: 1 | J21: 1 | K21: 1 | L21: =SUMPRODUCT(D21:K21,$D7:$K7) -> 5 | M21: = | N21: 5
A22: 2) | B22: 2a) | C22: Must represent sector 1 (S11, S12) ≥ 1 | D22: 1 | E22: 1 | F22: 0 | G22: 0 | H22: 0 | I22: 0 | J22: 0 | K22: 0 | L22: =SUMPRODUCT(D22:K22,$D7:$K7) -> 2 | M22: >= | N22: 1
B23: 2b) | C23: Must represent sector 2 (S21, S22) ≥ 1 | D23: 0 | E23: 0 | F23: 1 | G23: 1 | H23: 0 | I23: 0 | J23: 0 | K23: 0 | L23: =SUMPRODUCT(D23:K23,$D7:$K7) -> 1 | M23: >= | N23: 1
B24: 2c) | C24: Must represent sector 3 (S31, S32) ≥ 1 | D24: 0 | E24: 0 | F24: 0 | G24: 0 | H24: 1 | I24: 1 | J24: 0 | K24: 0 | L24: =SUMPRODUCT(D24:K24,$D7:$K7) -> 1 | M24: >= | N24: 1
B25: 2d) | C25: Must represent sector 4 (S41, S42) ≥ 1 | D25: 0 | E25: 0 | F25: 0 | G25: 0 | H25: 0 | I25: 0 | J25: 1 | K25: 1 | L25: =SUMPRODUCT(D25:K25,$D7:$K7) -> 1 | M25: >= | N25: 1
B26: 3) | C26: At most one from R3 group | D26: 1 | E26: 0 | F26: 1 | G26: 0 | H26: 0 | I26: 0 | J26: 0 | K26: 1 | L26: =SUMPRODUCT(D26:K26,$D7:$K7) -> 1 | M26: <= | N26: 1
B27: 4) | C27: At least two from R1 group | D27: 0 | E27: 1 | F27: 0 | G27: 0 | H27: 1 | I27: 0 | J27: 0 | K27: 0 | L27: =SUMPRODUCT(D27:K27,$D7:$K7) -> 2 | M27: >= | N27: 2
B28: 5) | C28: R3 asset (X1, X3, X8) can be selected only if at least one R2 asset (X4, X6, or X7) is selected. | D28: 1 | E28: 0 | F28: 1 | G28: -1 | H28: 0 | I28: -1 | J28: -1 | K28: 1 | L28: =SUMPRODUCT(D28:K28,$D7:$K7) -> -1 | M28: <= | N28: 0
B29: 6) | C29: Must represent atleast one from R2 assets | D29: 0 | E29: 0 | F29: 0 | G29: 1 | H29: 0 | I29: 1 | J29: 1 | K29: 0 | L29: =SUMPRODUCT(D29:K29,$D7:$K7) -> 2 | M29: >= | N29: 1 | Z29: S

Sheet Summary Sheet
D2: LP Model summary sheet
C3: Symbol | D3: Company | E3: Sector Code | F3: Sub Sector Code for Chosen Assets | G3: Average 4 year Return | H3: Standard Deviation | I3: Risk Category (R1 / R2 /R3) | J3: Proportion of Investment
C4: (ASX:PME) | D4: Pro Medicus Limited | E4: S1 | F4: S11 | G4: ='1.b Sample (Return and Risk)'!C56 -> 0.045530186 | H4: ='1.b Sample (Return and Risk)'!C57 -> 0.10936386 | I4: R3 | J4: ='2.a. LP Modelling '!D7 -> 0.05
C5: (ASX.CSL) | D5: CSL Limited | F5: S12 | G5: ='1.b Sample (Return and Risk)'!D56 -> 0.0018673008 | H5: ='1.b Sample (Return and Risk)'!D57 -> 0.049762204 | I5: R1 | J5: ='2.a. LP Modelling '!E7 -> 0.1
C6: (ASX:XRO) | D6: Xero Limited | E6: S2 | F6: S21 | G6: ='1.b Sample (Return and Risk)'!E56 -> 0.011564818 | H6: ='1.b Sample (Return and Risk)'!E57 -> 0.094151229 | I6: R3 | J6: ='2.a. LP Modelling '!F7 -> 0.05
C7: (ASX.NXT) | D7: NEXTDC Limited | F7: S22 | G7: ='1.b Sample (Return and Risk)'!F56 -> 0.0084991829 | H7: ='1.b Sample (Return and Risk)'!F57 -> 0.083522881 | I7: R2 | J7: ='2.a. LP Modelling '!G7 -> 0.1
C8: (ASX:TLS) | D8: Telstra Group Limited | E8: S3 | F8: S31 | G8: ='1.b Sample (Return and Risk)'!G56 -> 0.0055431375 | H8: ='1.b Sample (Return and Risk)'!G57 -> 0.035698466 | I8: R1 | J8: ='2.a. LP Modelling '!H7 -> 0.4
C9: (ASX.TPG) | D9: TPG Telecom Limited | F9: S32 | G9: ='1.b Sample (Return and Risk)'!H56 -> -0.0082112647 | H9: ='1.b Sample (Return and Risk)'!H57 -> 0.07254004 | I9: R2 | J9: ='2.a. LP Modelling '!I7 -> 0.05
C10: (ASX:CBA) | D10: Commonwealth Bank | E10: S4 | F10: S41 | G10: ='1.b Sample (Return and Risk)'!I56 -> 0.015632543 | H10: ='1.b Sample (Return and Risk)'!I57 -> 0.062967476 | I10: R2 | J10: ='2.a. LP Modelling '!J7 -> 0.2
C11: (ASX.AFG) | D11: Australian Finance Group Limited | F11: S42 | G11: ='1.b Sample (Return and Risk)'!J56 -> -0.0062336918 | H11: ='1.b Sample (Return and Risk)'!J57 -> 0.093580805 | I11: R3 | J11: ='2.a. LP Modelling '!K7 -> 0.05
D13: Optimal Value | E13: ='2.a. LP Modelling '!D15 -> 0.008495
D17: ILP Model summary sheet
C18: Symbol | D18: Company | E18: Sector Code | F18: Sub Sector Code for Chosen Assets | G18: Average 4 year return | H18: Standard Deviation | I18: Risk Category (R1 / R2 /R3) | J18: Investment
C19: (ASX:PME) | D19: Pro Medicus Limited | E19: S1 | F19: S11 | G19: 0.045530186 | H19: 0.10936386 | I19: R3 | J19: ='3.a ILP modelling'!D7 -> 1 | K19: YES
C20: (ASX.CSL) | D20: CSL Limited | F20: S12 | G20: 0.0018673008 | H20: 0.049762204 | I20: R1 | J20: ='3.a ILP modelling'!E7 -> 1 | K20: YES
C21: (ASX:XRO) | D21: Xero Limited | E21: S2 | F21: S21 | G21: 0.011564818 | H21: 0.094151229 | I21: R3 | J21: ='3.a ILP modelling'!F7 -> 0 | K21: NO
C22: (ASX.NXT) | D22: NEXTDC Limited | F22: S22 | G22: 0.0084991829 | H22: 0.083522881 | I22: R2 | J22: ='3.a ILP modelling'!G7 -> 1 | K22: YES
C23: (ASX:TLS) | D23: Telstra Group Limited | E23: S3 | F23: S31 | G23: 0.0055431375 | H23: 0.035698466 | I23: R1 | J23: ='3.a ILP modelling'!H7 -> 1 | K23: YES
C24: (ASX.TPG) | D24: TPG Telecom Limited | F24: S32 | G24: -0.0082112647 | H24: 0.07254004 | I24: R2 | J24: ='3.a ILP modelling'!I7 -> 0 | K24: NO
C25: (ASX:CBA) | D25: Commonwealth Bank | E25: S4 | F25: S41 | G25: 0.015632543 | H25: 0.062967476 | I25: R2 | J25: ='3.a ILP modelling'!J7 -> 1 | K25: YES
C26: (ASX.AFG) | D26: Australian Finance Group Limited | F26: S42 | G26: -0.0062336918 | H26: 0.093580805 | I26: R3 | J26: ='3.a ILP modelling'!K7 -> 0 | K26: NO
D28: Optimal Value | E28: ='3.a ILP modelling'!D15 -> 0.077
